2021-11-24 11:03:40,410 ERROR: Exception on /new_study/data_analysis/4fd4455c-f3c0-4415-a057-f3471ffdb6a3 [GET] [in C:\Users\noudy\PycharmProjects\untitled2\PLS\lib\site-packages\flask\app.py:1457]
Traceback (most recent call last):
  File "C:\Users\noudy\PycharmProjects\untitled2\PLS\lib\site-packages\flask\app.py", line 2073, in wsgi_app
    response = self.full_dispatch_request()
  File "C:\Users\noudy\PycharmProjects\untitled2\PLS\lib\site-packages\flask\app.py", line 1518, in full_dispatch_request
    rv = self.handle_user_exception(e)
  File "C:\Users\noudy\PycharmProjects\untitled2\PLS\lib\site-packages\flask\app.py", line 1516, in full_dispatch_request
    rv = self.dispatch_request()
  File "C:\Users\noudy\PycharmProjects\untitled2\PLS\lib\site-packages\flask\app.py", line 1502, in dispatch_request
    return self.ensure_sync(self.view_functions[rule.endpoint])(**req.view_args)
  File "C:\Users\noudy\PycharmProjects\untitled2\PLS\lib\site-packages\flask_login\utils.py", line 272, in decorated_view
    return func(*args, **kwargs)
  File "C:\Users\noudy\PycharmProjects\PLS\app\new_study\routes.py", line 844, in data_analysis
    df.to_csv(r'C:\Users\noudy\PycharmProjects\PLS\export.csv', index=False, header=True)
  File "C:\Users\noudy\PycharmProjects\untitled2\PLS\lib\site-packages\pandas\core\generic.py", line 3466, in to_csv
    return DataFrameRenderer(formatter).to_csv(
  File "C:\Users\noudy\PycharmProjects\untitled2\PLS\lib\site-packages\pandas\io\formats\format.py", line 1105, in to_csv
    csv_formatter.save()
  File "C:\Users\noudy\PycharmProjects\untitled2\PLS\lib\site-packages\pandas\io\formats\csvs.py", line 237, in save
    with get_handle(
  File "C:\Users\noudy\PycharmProjects\untitled2\PLS\lib\site-packages\pandas\io\common.py", line 702, in get_handle
    handle = open(
PermissionError: [Errno 13] Permission denied: 'C:\\Users\\noudy\\PycharmProjects\\PLS\\export.csv'
2021-11-24 11:03:59,479 INFO: Microblog startup [in C:\Users\noudy\PycharmProjects\PLS\app\__init__.py:78]
2021-11-27 20:24:09,101 INFO: Microblog startup [in C:\Users\noudy\PycharmProjects\PLS\app\__init__.py:78]
2021-11-27 20:30:37,847 INFO: Microblog startup [in C:\Users\noudy\PycharmProjects\PLS\app\__init__.py:78]
2021-11-27 20:31:13,317 INFO: Microblog startup [in C:\Users\noudy\PycharmProjects\PLS\app\__init__.py:78]
2021-11-27 20:32:47,739 INFO: Microblog startup [in C:\Users\noudy\PycharmProjects\PLS\app\__init__.py:78]
2021-11-27 20:49:06,950 INFO: Microblog startup [in C:\Users\noudy\PycharmProjects\PLS\app\__init__.py:78]
2021-11-27 20:49:10,188 ERROR: Exception on /new_study/data_analysis/4fd4455c-f3c0-4415-a057-f3471ffdb6a3 [GET] [in C:\Users\noudy\PycharmProjects\untitled2\PLS\lib\site-packages\flask\app.py:1457]
Traceback (most recent call last):
  File "C:\Users\noudy\PycharmProjects\untitled2\PLS\lib\site-packages\flask\app.py", line 2073, in wsgi_app
    response = self.full_dispatch_request()
  File "C:\Users\noudy\PycharmProjects\untitled2\PLS\lib\site-packages\flask\app.py", line 1518, in full_dispatch_request
    rv = self.handle_user_exception(e)
  File "C:\Users\noudy\PycharmProjects\untitled2\PLS\lib\site-packages\flask\app.py", line 1516, in full_dispatch_request
    rv = self.dispatch_request()
  File "C:\Users\noudy\PycharmProjects\untitled2\PLS\lib\site-packages\flask\app.py", line 1502, in dispatch_request
    return self.ensure_sync(self.view_functions[rule.endpoint])(**req.view_args)
  File "C:\Users\noudy\PycharmProjects\untitled2\PLS\lib\site-packages\flask_login\utils.py", line 272, in decorated_view
    return func(*args, **kwargs)
  File "C:\Users\noudy\PycharmProjects\PLS\app\new_study\routes.py", line 852, in data_analysis
    covariance('PE1', 'EE1', df)
  File "C:\Users\noudy\PycharmProjects\PLS\app\new_study\functions.py", line 114, in covariance
    avg_item2 = sum(scores_item2) / len(scores_item2)
ZeroDivisionError: division by zero
2021-11-27 20:50:13,957 INFO: Microblog startup [in C:\Users\noudy\PycharmProjects\PLS\app\__init__.py:78]
2021-11-27 20:51:39,755 INFO: Microblog startup [in C:\Users\noudy\PycharmProjects\PLS\app\__init__.py:78]
2021-11-27 20:59:08,450 INFO: Microblog startup [in C:\Users\noudy\PycharmProjects\PLS\app\__init__.py:78]
2021-11-27 21:00:20,932 INFO: Microblog startup [in C:\Users\noudy\PycharmProjects\PLS\app\__init__.py:78]
2021-11-27 21:01:03,656 INFO: Microblog startup [in C:\Users\noudy\PycharmProjects\PLS\app\__init__.py:78]
2021-11-27 21:01:46,145 INFO: Microblog startup [in C:\Users\noudy\PycharmProjects\PLS\app\__init__.py:78]
2021-11-27 21:02:12,103 INFO: Microblog startup [in C:\Users\noudy\PycharmProjects\PLS\app\__init__.py:78]
2021-11-27 21:02:42,547 INFO: Microblog startup [in C:\Users\noudy\PycharmProjects\PLS\app\__init__.py:78]
2021-11-27 21:02:58,890 INFO: Microblog startup [in C:\Users\noudy\PycharmProjects\PLS\app\__init__.py:78]
2021-11-27 21:07:58,866 INFO: Microblog startup [in C:\Users\noudy\PycharmProjects\PLS\app\__init__.py:78]
2021-11-27 21:13:54,889 INFO: Microblog startup [in C:\Users\noudy\PycharmProjects\PLS\app\__init__.py:78]
2021-11-27 21:14:21,059 INFO: Microblog startup [in C:\Users\noudy\PycharmProjects\PLS\app\__init__.py:78]
2021-11-27 21:14:25,819 ERROR: Exception on /new_study/data_analysis/4fd4455c-f3c0-4415-a057-f3471ffdb6a3 [GET] [in C:\Users\noudy\PycharmProjects\untitled2\PLS\lib\site-packages\flask\app.py:1457]
Traceback (most recent call last):
  File "C:\Users\noudy\PycharmProjects\untitled2\PLS\lib\site-packages\flask\app.py", line 2073, in wsgi_app
    response = self.full_dispatch_request()
  File "C:\Users\noudy\PycharmProjects\untitled2\PLS\lib\site-packages\flask\app.py", line 1518, in full_dispatch_request
    rv = self.handle_user_exception(e)
  File "C:\Users\noudy\PycharmProjects\untitled2\PLS\lib\site-packages\flask\app.py", line 1516, in full_dispatch_request
    rv = self.dispatch_request()
  File "C:\Users\noudy\PycharmProjects\untitled2\PLS\lib\site-packages\flask\app.py", line 1502, in dispatch_request
    return self.ensure_sync(self.view_functions[rule.endpoint])(**req.view_args)
  File "C:\Users\noudy\PycharmProjects\untitled2\PLS\lib\site-packages\flask_login\utils.py", line 272, in decorated_view
    return func(*args, **kwargs)
  File "C:\Users\noudy\PycharmProjects\PLS\app\new_study\routes.py", line 854, in data_analysis
    correlation_matrix(df)
  File "C:\Users\noudy\PycharmProjects\PLS\app\new_study\functions.py", line 134, in correlation_matrix
    data[item] = [pearson_correlation(item, lv2, dataset) for lv2 in items]
  File "C:\Users\noudy\PycharmProjects\PLS\app\new_study\functions.py", line 134, in <listcomp>
    data[item] = [pearson_correlation(item, lv2, dataset) for lv2 in items]
  File "C:\Users\noudy\PycharmProjects\PLS\app\new_study\functions.py", line 123, in pearson_correlation
    covar = covariance(lv1, lv2, dataset)
  File "C:\Users\noudy\PycharmProjects\PLS\app\new_study\functions.py", line 113, in covariance
    avg_item2 = sum(scores_item2) / len(scores_item2)
ZeroDivisionError: division by zero
2021-11-27 21:15:19,553 INFO: Microblog startup [in C:\Users\noudy\PycharmProjects\PLS\app\__init__.py:78]
2021-11-27 21:15:20,606 ERROR: Exception on /new_study/data_analysis/4fd4455c-f3c0-4415-a057-f3471ffdb6a3 [GET] [in C:\Users\noudy\PycharmProjects\untitled2\PLS\lib\site-packages\flask\app.py:1457]
Traceback (most recent call last):
  File "C:\Users\noudy\PycharmProjects\untitled2\PLS\lib\site-packages\flask\app.py", line 2073, in wsgi_app
    response = self.full_dispatch_request()
  File "C:\Users\noudy\PycharmProjects\untitled2\PLS\lib\site-packages\flask\app.py", line 1518, in full_dispatch_request
    rv = self.handle_user_exception(e)
  File "C:\Users\noudy\PycharmProjects\untitled2\PLS\lib\site-packages\flask\app.py", line 1516, in full_dispatch_request
    rv = self.dispatch_request()
  File "C:\Users\noudy\PycharmProjects\untitled2\PLS\lib\site-packages\flask\app.py", line 1502, in dispatch_request
    return self.ensure_sync(self.view_functions[rule.endpoint])(**req.view_args)
  File "C:\Users\noudy\PycharmProjects\untitled2\PLS\lib\site-packages\flask_login\utils.py", line 272, in decorated_view
    return func(*args, **kwargs)
  File "C:\Users\noudy\PycharmProjects\PLS\app\new_study\routes.py", line 854, in data_analysis
    correlation_matrix(df)
  File "C:\Users\noudy\PycharmProjects\PLS\app\new_study\functions.py", line 135, in correlation_matrix
    data[item] = [pearson_correlation(item, lv2, dataset) for lv2 in items]
  File "C:\Users\noudy\PycharmProjects\PLS\app\new_study\functions.py", line 135, in <listcomp>
    data[item] = [pearson_correlation(item, lv2, dataset) for lv2 in items]
  File "C:\Users\noudy\PycharmProjects\PLS\app\new_study\functions.py", line 123, in pearson_correlation
    covar = covariance(lv1, lv2, dataset)
  File "C:\Users\noudy\PycharmProjects\PLS\app\new_study\functions.py", line 113, in covariance
    avg_item2 = sum(scores_item2) / len(scores_item2)
ZeroDivisionError: division by zero
2021-11-27 21:15:54,711 INFO: Microblog startup [in C:\Users\noudy\PycharmProjects\PLS\app\__init__.py:78]
