2021-11-17 14:24:56,795 ERROR: Exception on /new_study/summary_results/a13a3037-1e65-4b4b-896e-c06a397e24d5 [GET] [in C:\Users\noudy\PycharmProjects\untitled2\PLS\lib\site-packages\flask\app.py:1457]
Traceback (most recent call last):
  File "C:\Users\noudy\PycharmProjects\untitled2\PLS\lib\site-packages\sqlalchemy\sql\base.py", line 1690, in _entity_namespace_key
    return getattr(ns, key)
AttributeError: type object 'Question' has no attribute 'questionnaire_id'

The above exception was the direct cause of the following exception:

Traceback (most recent call last):
  File "C:\Users\noudy\PycharmProjects\untitled2\PLS\lib\site-packages\flask\app.py", line 2073, in wsgi_app
    response = self.full_dispatch_request()
  File "C:\Users\noudy\PycharmProjects\untitled2\PLS\lib\site-packages\flask\app.py", line 1518, in full_dispatch_request
    rv = self.handle_user_exception(e)
  File "C:\Users\noudy\PycharmProjects\untitled2\PLS\lib\site-packages\flask\app.py", line 1516, in full_dispatch_request
    rv = self.dispatch_request()
  File "C:\Users\noudy\PycharmProjects\untitled2\PLS\lib\site-packages\flask\app.py", line 1502, in dispatch_request
    return self.ensure_sync(self.view_functions[rule.endpoint])(**req.view_args)
  File "C:\Users\noudy\PycharmProjects\untitled2\PLS\lib\site-packages\flask_login\utils.py", line 272, in decorated_view
    return func(*args, **kwargs)
  File "C:\Users\noudy\PycharmProjects\PLS\app\new_study\routes.py", line 739, in summary_results
    quest = Question.query.filter_by(question=quest_name, questionnaire_id=questionnaire.id).first()
  File "C:\Users\noudy\PycharmProjects\untitled2\PLS\lib\site-packages\sqlalchemy\orm\query.py", line 1793, in filter_by
    clauses = [
  File "C:\Users\noudy\PycharmProjects\untitled2\PLS\lib\site-packages\sqlalchemy\orm\query.py", line 1794, in <listcomp>
    _entity_namespace_key(from_entity, key) == value
  File "C:\Users\noudy\PycharmProjects\untitled2\PLS\lib\site-packages\sqlalchemy\sql\base.py", line 1692, in _entity_namespace_key
    util.raise_(
  File "C:\Users\noudy\PycharmProjects\untitled2\PLS\lib\site-packages\sqlalchemy\util\compat.py", line 207, in raise_
    raise exception
sqlalchemy.exc.InvalidRequestError: Entity namespace for "question" has no property "questionnaire_id"
2021-11-17 14:30:30,625 INFO: Microblog startup [in C:\Users\noudy\PycharmProjects\PLS\app\__init__.py:78]
2021-11-17 14:30:34,415 ERROR: Exception on /new_study/summary_results/a13a3037-1e65-4b4b-896e-c06a397e24d5 [GET] [in C:\Users\noudy\PycharmProjects\untitled2\PLS\lib\site-packages\flask\app.py:1457]
Traceback (most recent call last):
  File "C:\Users\noudy\PycharmProjects\untitled2\PLS\lib\site-packages\sqlalchemy\sql\base.py", line 1690, in _entity_namespace_key
    return getattr(ns, key)
AttributeError: type object 'Answer' has no attribute 'user_id'

The above exception was the direct cause of the following exception:

Traceback (most recent call last):
  File "C:\Users\noudy\PycharmProjects\untitled2\PLS\lib\site-packages\flask\app.py", line 2073, in wsgi_app
    response = self.full_dispatch_request()
  File "C:\Users\noudy\PycharmProjects\untitled2\PLS\lib\site-packages\flask\app.py", line 1518, in full_dispatch_request
    rv = self.handle_user_exception(e)
  File "C:\Users\noudy\PycharmProjects\untitled2\PLS\lib\site-packages\flask\app.py", line 1516, in full_dispatch_request
    rv = self.dispatch_request()
  File "C:\Users\noudy\PycharmProjects\untitled2\PLS\lib\site-packages\flask\app.py", line 1502, in dispatch_request
    return self.ensure_sync(self.view_functions[rule.endpoint])(**req.view_args)
  File "C:\Users\noudy\PycharmProjects\untitled2\PLS\lib\site-packages\flask_login\utils.py", line 272, in decorated_view
    return func(*args, **kwargs)
  File "C:\Users\noudy\PycharmProjects\PLS\app\new_study\routes.py", line 741, in summary_results
    answer = Answer.query.filter_by(question_id=quest.id, user_id=current_user.id).first()
  File "C:\Users\noudy\PycharmProjects\untitled2\PLS\lib\site-packages\sqlalchemy\orm\query.py", line 1793, in filter_by
    clauses = [
  File "C:\Users\noudy\PycharmProjects\untitled2\PLS\lib\site-packages\sqlalchemy\orm\query.py", line 1794, in <listcomp>
    _entity_namespace_key(from_entity, key) == value
  File "C:\Users\noudy\PycharmProjects\untitled2\PLS\lib\site-packages\sqlalchemy\sql\base.py", line 1692, in _entity_namespace_key
    util.raise_(
  File "C:\Users\noudy\PycharmProjects\untitled2\PLS\lib\site-packages\sqlalchemy\util\compat.py", line 207, in raise_
    raise exception
sqlalchemy.exc.InvalidRequestError: Entity namespace for "answer" has no property "user_id"
2021-11-17 14:30:59,476 INFO: Microblog startup [in C:\Users\noudy\PycharmProjects\PLS\app\__init__.py:78]
2021-11-17 14:30:59,735 ERROR: Exception on /new_study/summary_results/a13a3037-1e65-4b4b-896e-c06a397e24d5 [GET] [in C:\Users\noudy\PycharmProjects\untitled2\PLS\lib\site-packages\flask\app.py:1457]
Traceback (most recent call last):
  File "C:\Users\noudy\PycharmProjects\untitled2\PLS\lib\site-packages\flask\app.py", line 2073, in wsgi_app
    response = self.full_dispatch_request()
  File "C:\Users\noudy\PycharmProjects\untitled2\PLS\lib\site-packages\flask\app.py", line 1518, in full_dispatch_request
    rv = self.handle_user_exception(e)
  File "C:\Users\noudy\PycharmProjects\untitled2\PLS\lib\site-packages\flask\app.py", line 1516, in full_dispatch_request
    rv = self.dispatch_request()
  File "C:\Users\noudy\PycharmProjects\untitled2\PLS\lib\site-packages\flask\app.py", line 1502, in dispatch_request
    return self.ensure_sync(self.view_functions[rule.endpoint])(**req.view_args)
  File "C:\Users\noudy\PycharmProjects\untitled2\PLS\lib\site-packages\flask_login\utils.py", line 272, in decorated_view
    return func(*args, **kwargs)
  File "C:\Users\noudy\PycharmProjects\PLS\app\new_study\routes.py", line 741, in summary_results
    answer = Answer.query.filter_by(question_id=quest.id, case_id=case_id).first()
AttributeError: 'NoneType' object has no attribute 'id'
2021-11-17 14:31:42,313 INFO: Microblog startup [in C:\Users\noudy\PycharmProjects\PLS\app\__init__.py:78]
2021-11-17 14:32:24,368 INFO: Microblog startup [in C:\Users\noudy\PycharmProjects\PLS\app\__init__.py:78]
2021-11-17 14:42:59,938 INFO: Microblog startup [in C:\Users\noudy\PycharmProjects\PLS\app\__init__.py:78]
2021-11-17 14:44:25,677 INFO: Microblog startup [in C:\Users\noudy\PycharmProjects\PLS\app\__init__.py:78]
2021-11-17 14:51:17,976 INFO: Microblog startup [in C:\Users\noudy\PycharmProjects\PLS\app\__init__.py:78]
2021-11-17 14:52:16,275 INFO: Microblog startup [in C:\Users\noudy\PycharmProjects\PLS\app\__init__.py:78]
2021-11-17 14:54:53,622 INFO: Microblog startup [in C:\Users\noudy\PycharmProjects\PLS\app\__init__.py:78]
2021-11-17 15:00:42,597 INFO: Microblog startup [in C:\Users\noudy\PycharmProjects\PLS\app\__init__.py:78]
2021-11-17 15:29:02,146 INFO: Microblog startup [in C:\Users\noudy\PycharmProjects\PLS\app\__init__.py:78]
2021-11-17 15:32:38,418 INFO: Microblog startup [in C:\Users\noudy\PycharmProjects\PLS\app\__init__.py:78]
