2021-12-24 12:00:35,279 ERROR: Exception on /new_study/utaut/881128b6-4b61-48fd-8cc5-c3d17a58f079 [GET] [in C:\Users\noudy\PycharmProjects\untitled2\PLS\lib\site-packages\flask\app.py:1457]
Traceback (most recent call last):
  File "C:\Users\noudy\PycharmProjects\untitled2\PLS\lib\site-packages\sqlalchemy\orm\clsregistry.py", line 393, in _resolve_name
    rval = d[token]
  File "C:\Users\noudy\PycharmProjects\untitled2\PLS\lib\site-packages\sqlalchemy\util\_collections.py", line 746, in __missing__
    self[key] = val = self.creator(key)
  File "C:\Users\noudy\PycharmProjects\untitled2\PLS\lib\site-packages\sqlalchemy\orm\clsregistry.py", line 372, in _access_cls
    return self.fallback[key]
KeyError: ''

The above exception was the direct cause of the following exception:

Traceback (most recent call last):
  File "C:\Users\noudy\PycharmProjects\untitled2\PLS\lib\site-packages\flask\app.py", line 2072, in wsgi_app
    ctx.push()
  File "C:\Users\noudy\PycharmProjects\untitled2\PLS\lib\site-packages\flask\ctx.py", line 404, in push
    self.session = session_interface.open_session(self.app, self.request)
  File "C:\Users\noudy\PycharmProjects\untitled2\PLS\lib\site-packages\flask_session\sessions.py", line 344, in open_session
    data = self.cache.get(self.key_prefix + sid)
  File "C:\Users\noudy\PycharmProjects\untitled2\PLS\lib\site-packages\cachelib\file.py", line 186, in get
    return pickle.load(f)
  File "C:\Users\noudy\PycharmProjects\untitled2\PLS\lib\site-packages\sqlalchemy\orm\state.py", line 575, in __setstate__
    state_dict["manager"](self, inst, state_dict)
  File "C:\Users\noudy\PycharmProjects\untitled2\PLS\lib\site-packages\sqlalchemy\orm\instrumentation.py", line 497, in __call__
    manager.mapper._check_configure()
  File "C:\Users\noudy\PycharmProjects\untitled2\PLS\lib\site-packages\sqlalchemy\orm\mapper.py", line 1916, in _check_configure
    _configure_registries({self.registry}, cascade=True)
  File "C:\Users\noudy\PycharmProjects\untitled2\PLS\lib\site-packages\sqlalchemy\orm\mapper.py", line 3429, in _configure_registries
    _do_configure_registries(registries, cascade)
  File "C:\Users\noudy\PycharmProjects\untitled2\PLS\lib\site-packages\sqlalchemy\orm\mapper.py", line 3468, in _do_configure_registries
    mapper._post_configure_properties()
  File "C:\Users\noudy\PycharmProjects\untitled2\PLS\lib\site-packages\sqlalchemy\orm\mapper.py", line 1933, in _post_configure_properties
    prop.init()
  File "C:\Users\noudy\PycharmProjects\untitled2\PLS\lib\site-packages\sqlalchemy\orm\interfaces.py", line 231, in init
    self.do_init()
  File "C:\Users\noudy\PycharmProjects\untitled2\PLS\lib\site-packages\sqlalchemy\orm\relationships.py", line 2150, in do_init
    self._process_dependent_arguments()
  File "C:\Users\noudy\PycharmProjects\untitled2\PLS\lib\site-packages\sqlalchemy\orm\relationships.py", line 2245, in _process_dependent_arguments
    self.target = self.entity.persist_selectable
  File "C:\Users\noudy\PycharmProjects\untitled2\PLS\lib\site-packages\sqlalchemy\util\langhelpers.py", line 1113, in __get__
    obj.__dict__[self.__name__] = result = self.fget(obj)
  File "C:\Users\noudy\PycharmProjects\untitled2\PLS\lib\site-packages\sqlalchemy\orm\relationships.py", line 2112, in entity
    argument = self._clsregistry_resolve_name(self.argument)()
  File "C:\Users\noudy\PycharmProjects\untitled2\PLS\lib\site-packages\sqlalchemy\orm\clsregistry.py", line 397, in _resolve_name
    self._raise_for_name(name, err)
  File "C:\Users\noudy\PycharmProjects\untitled2\PLS\lib\site-packages\sqlalchemy\orm\clsregistry.py", line 375, in _raise_for_name
    util.raise_(
  File "C:\Users\noudy\PycharmProjects\untitled2\PLS\lib\site-packages\sqlalchemy\util\compat.py", line 207, in raise_
    raise exception
sqlalchemy.exc.InvalidRequestError: When initializing mapper mapped class CoreVariable->core_variable, expression '' failed to locate a name (''). If this is a class name, consider adding this relationship() to the <class 'app.models.CoreVariable'> class after both dependent classes have been defined.
2021-12-24 12:00:35,300 ERROR: Request finalizing failed with an error while handling an error [in C:\Users\noudy\PycharmProjects\untitled2\PLS\lib\site-packages\flask\app.py:1545]
Traceback (most recent call last):
  File "C:\Users\noudy\PycharmProjects\untitled2\PLS\lib\site-packages\sqlalchemy\orm\clsregistry.py", line 393, in _resolve_name
    rval = d[token]
  File "C:\Users\noudy\PycharmProjects\untitled2\PLS\lib\site-packages\sqlalchemy\util\_collections.py", line 746, in __missing__
    self[key] = val = self.creator(key)
  File "C:\Users\noudy\PycharmProjects\untitled2\PLS\lib\site-packages\sqlalchemy\orm\clsregistry.py", line 372, in _access_cls
    return self.fallback[key]
KeyError: ''

The above exception was the direct cause of the following exception:

Traceback (most recent call last):
  File "C:\Users\noudy\PycharmProjects\untitled2\PLS\lib\site-packages\flask\app.py", line 2072, in wsgi_app
    ctx.push()
  File "C:\Users\noudy\PycharmProjects\untitled2\PLS\lib\site-packages\flask\ctx.py", line 404, in push
    self.session = session_interface.open_session(self.app, self.request)
  File "C:\Users\noudy\PycharmProjects\untitled2\PLS\lib\site-packages\flask_session\sessions.py", line 344, in open_session
    data = self.cache.get(self.key_prefix + sid)
  File "C:\Users\noudy\PycharmProjects\untitled2\PLS\lib\site-packages\cachelib\file.py", line 186, in get
    return pickle.load(f)
  File "C:\Users\noudy\PycharmProjects\untitled2\PLS\lib\site-packages\sqlalchemy\orm\state.py", line 575, in __setstate__
    state_dict["manager"](self, inst, state_dict)
  File "C:\Users\noudy\PycharmProjects\untitled2\PLS\lib\site-packages\sqlalchemy\orm\instrumentation.py", line 497, in __call__
    manager.mapper._check_configure()
  File "C:\Users\noudy\PycharmProjects\untitled2\PLS\lib\site-packages\sqlalchemy\orm\mapper.py", line 1916, in _check_configure
    _configure_registries({self.registry}, cascade=True)
  File "C:\Users\noudy\PycharmProjects\untitled2\PLS\lib\site-packages\sqlalchemy\orm\mapper.py", line 3429, in _configure_registries
    _do_configure_registries(registries, cascade)
  File "C:\Users\noudy\PycharmProjects\untitled2\PLS\lib\site-packages\sqlalchemy\orm\mapper.py", line 3468, in _do_configure_registries
    mapper._post_configure_properties()
  File "C:\Users\noudy\PycharmProjects\untitled2\PLS\lib\site-packages\sqlalchemy\orm\mapper.py", line 1933, in _post_configure_properties
    prop.init()
  File "C:\Users\noudy\PycharmProjects\untitled2\PLS\lib\site-packages\sqlalchemy\orm\interfaces.py", line 231, in init
    self.do_init()
  File "C:\Users\noudy\PycharmProjects\untitled2\PLS\lib\site-packages\sqlalchemy\orm\relationships.py", line 2150, in do_init
    self._process_dependent_arguments()
  File "C:\Users\noudy\PycharmProjects\untitled2\PLS\lib\site-packages\sqlalchemy\orm\relationships.py", line 2245, in _process_dependent_arguments
    self.target = self.entity.persist_selectable
  File "C:\Users\noudy\PycharmProjects\untitled2\PLS\lib\site-packages\sqlalchemy\util\langhelpers.py", line 1113, in __get__
    obj.__dict__[self.__name__] = result = self.fget(obj)
  File "C:\Users\noudy\PycharmProjects\untitled2\PLS\lib\site-packages\sqlalchemy\orm\relationships.py", line 2112, in entity
    argument = self._clsregistry_resolve_name(self.argument)()
  File "C:\Users\noudy\PycharmProjects\untitled2\PLS\lib\site-packages\sqlalchemy\orm\clsregistry.py", line 397, in _resolve_name
    self._raise_for_name(name, err)
  File "C:\Users\noudy\PycharmProjects\untitled2\PLS\lib\site-packages\sqlalchemy\orm\clsregistry.py", line 375, in _raise_for_name
    util.raise_(
  File "C:\Users\noudy\PycharmProjects\untitled2\PLS\lib\site-packages\sqlalchemy\util\compat.py", line 207, in raise_
    raise exception
sqlalchemy.exc.InvalidRequestError: When initializing mapper mapped class CoreVariable->core_variable, expression '' failed to locate a name (''). If this is a class name, consider adding this relationship() to the <class 'app.models.CoreVariable'> class after both dependent classes have been defined.

During handling of the above exception, another exception occurred:

Traceback (most recent call last):
  File "C:\Users\noudy\PycharmProjects\untitled2\PLS\lib\site-packages\flask\app.py", line 1540, in finalize_request
    response = self.process_response(response)
  File "C:\Users\noudy\PycharmProjects\untitled2\PLS\lib\site-packages\flask\app.py", line 1885, in process_response
    response = self.ensure_sync(func)(response)
  File "C:\Users\noudy\PycharmProjects\untitled2\PLS\lib\site-packages\flask_login\login_manager.py", line 399, in _update_remember_cookie
    if '_remember' not in session and \
TypeError: argument of type 'NoneType' is not iterable
2021-12-24 12:04:51,068 INFO: Microblog startup [in C:\Users\noudy\PycharmProjects\PLS\app\__init__.py:82]
