2021-11-18 17:17:54,991 ERROR: Exception on /new_study/data_analysis/7431d4a5-bbe8-47c2-828f-877210b9cceb [GET] [in C:\Users\noudy\PycharmProjects\untitled2\PLS\lib\site-packages\flask\app.py:1457]
Traceback (most recent call last):
  File "C:\Users\noudy\PycharmProjects\untitled2\PLS\lib\site-packages\flask\app.py", line 2073, in wsgi_app
    response = self.full_dispatch_request()
  File "C:\Users\noudy\PycharmProjects\untitled2\PLS\lib\site-packages\flask\app.py", line 1518, in full_dispatch_request
    rv = self.handle_user_exception(e)
  File "C:\Users\noudy\PycharmProjects\untitled2\PLS\lib\site-packages\flask\app.py", line 1516, in full_dispatch_request
    rv = self.dispatch_request()
  File "C:\Users\noudy\PycharmProjects\untitled2\PLS\lib\site-packages\flask\app.py", line 1502, in dispatch_request
    return self.ensure_sync(self.view_functions[rule.endpoint])(**req.view_args)
  File "C:\Users\noudy\PycharmProjects\untitled2\PLS\lib\site-packages\flask_login\utils.py", line 272, in decorated_view
    return func(*args, **kwargs)
  File "C:\Users\noudy\PycharmProjects\PLS\app\new_study\routes.py", line 836, in data_analysis
    plspm_calc = Plspm(df, config, Scheme.CENTROID)
  File "C:\Users\noudy\PycharmProjects\untitled2\PLS\lib\site-packages\plspm\plspm.py", line 65, in __init__
    correction = np.sqrt(filtered_data.shape[0] / (filtered_data.shape[0] - 1))
ZeroDivisionError: division by zero
2021-11-19 08:38:53,363 INFO: Microblog startup [in C:\Users\noudy\PycharmProjects\PLS\app\__init__.py:78]
2021-11-19 08:40:47,960 INFO: Microblog startup [in C:\Users\noudy\PycharmProjects\PLS\app\__init__.py:78]
2021-11-19 08:49:28,998 INFO: Microblog startup [in C:\Users\noudy\PycharmProjects\PLS\app\__init__.py:78]
2021-11-19 08:49:53,902 INFO: Microblog startup [in C:\Users\noudy\PycharmProjects\PLS\app\__init__.py:78]
2021-11-19 09:14:03,883 INFO: Microblog startup [in C:\Users\noudy\PycharmProjects\PLS\app\__init__.py:78]
2021-11-19 09:18:19,608 INFO: Microblog startup [in C:\Users\noudy\PycharmProjects\PLS\app\__init__.py:78]
2021-11-19 09:19:15,689 INFO: Microblog startup [in C:\Users\noudy\PycharmProjects\PLS\app\__init__.py:78]
2021-11-19 09:46:07,854 INFO: Microblog startup [in C:\Users\noudy\PycharmProjects\PLS\app\__init__.py:78]
2021-11-19 10:05:06,838 INFO: Microblog startup [in C:\Users\noudy\PycharmProjects\PLS\app\__init__.py:78]
2021-11-19 10:07:31,474 INFO: Microblog startup [in C:\Users\noudy\PycharmProjects\PLS\app\__init__.py:78]
2021-11-19 10:10:19,252 INFO: Microblog startup [in C:\Users\noudy\PycharmProjects\PLS\app\__init__.py:78]
2021-11-19 12:04:27,298 INFO: Microblog startup [in C:\Users\noudy\PycharmProjects\PLS\app\__init__.py:78]
2021-11-19 12:08:22,793 ERROR: Exception on /new_study/questionnaire/use_standard_questions_questionnaire/4fd4455c-f3c0-4415-a057-f3471ffdb6a3 [GET] [in C:\Users\noudy\PycharmProjects\untitled2\PLS\lib\site-packages\flask\app.py:1457]
Traceback (most recent call last):
  File "C:\Users\noudy\PycharmProjects\untitled2\PLS\lib\site-packages\flask\app.py", line 2073, in wsgi_app
    response = self.full_dispatch_request()
  File "C:\Users\noudy\PycharmProjects\untitled2\PLS\lib\site-packages\flask\app.py", line 1518, in full_dispatch_request
    rv = self.handle_user_exception(e)
  File "C:\Users\noudy\PycharmProjects\untitled2\PLS\lib\site-packages\flask\app.py", line 1516, in full_dispatch_request
    rv = self.dispatch_request()
  File "C:\Users\noudy\PycharmProjects\untitled2\PLS\lib\site-packages\flask\app.py", line 1502, in dispatch_request
    return self.ensure_sync(self.view_functions[rule.endpoint])(**req.view_args)
  File "C:\Users\noudy\PycharmProjects\untitled2\PLS\lib\site-packages\flask_login\utils.py", line 272, in decorated_view
    return func(*args, **kwargs)
  File "C:\Users\noudy\PycharmProjects\PLS\app\new_study\routes.py", line 433, in use_standard_questions_questionnaire
    corevariable = CoreVariable.query.filter_by(name=corresponding_questiongroup.title,
AttributeError: 'NoneType' object has no attribute 'title'
2021-11-19 12:08:26,049 ERROR: Exception on /new_study/questionnaire/use_standard_questions_questionnaire/4fd4455c-f3c0-4415-a057-f3471ffdb6a3 [GET] [in C:\Users\noudy\PycharmProjects\untitled2\PLS\lib\site-packages\flask\app.py:1457]
Traceback (most recent call last):
  File "C:\Users\noudy\PycharmProjects\untitled2\PLS\lib\site-packages\flask\app.py", line 2073, in wsgi_app
    response = self.full_dispatch_request()
  File "C:\Users\noudy\PycharmProjects\untitled2\PLS\lib\site-packages\flask\app.py", line 1518, in full_dispatch_request
    rv = self.handle_user_exception(e)
  File "C:\Users\noudy\PycharmProjects\untitled2\PLS\lib\site-packages\flask\app.py", line 1516, in full_dispatch_request
    rv = self.dispatch_request()
  File "C:\Users\noudy\PycharmProjects\untitled2\PLS\lib\site-packages\flask\app.py", line 1502, in dispatch_request
    return self.ensure_sync(self.view_functions[rule.endpoint])(**req.view_args)
  File "C:\Users\noudy\PycharmProjects\untitled2\PLS\lib\site-packages\flask_login\utils.py", line 272, in decorated_view
    return func(*args, **kwargs)
  File "C:\Users\noudy\PycharmProjects\PLS\app\new_study\routes.py", line 433, in use_standard_questions_questionnaire
    corevariable = CoreVariable.query.filter_by(name=corresponding_questiongroup.title,
AttributeError: 'NoneType' object has no attribute 'title'
2021-11-19 12:10:19,090 INFO: Microblog startup [in C:\Users\noudy\PycharmProjects\PLS\app\__init__.py:78]
2021-11-19 12:10:56,664 ERROR: Exception on /new_study/questionnaire/use_standard_questions_questionnaire/4fd4455c-f3c0-4415-a057-f3471ffdb6a3 [GET] [in C:\Users\noudy\PycharmProjects\untitled2\PLS\lib\site-packages\flask\app.py:1457]
Traceback (most recent call last):
  File "C:\Users\noudy\PycharmProjects\untitled2\PLS\lib\site-packages\flask\app.py", line 2073, in wsgi_app
    response = self.full_dispatch_request()
  File "C:\Users\noudy\PycharmProjects\untitled2\PLS\lib\site-packages\flask\app.py", line 1518, in full_dispatch_request
    rv = self.handle_user_exception(e)
  File "C:\Users\noudy\PycharmProjects\untitled2\PLS\lib\site-packages\flask\app.py", line 1516, in full_dispatch_request
    rv = self.dispatch_request()
  File "C:\Users\noudy\PycharmProjects\untitled2\PLS\lib\site-packages\flask\app.py", line 1502, in dispatch_request
    return self.ensure_sync(self.view_functions[rule.endpoint])(**req.view_args)
  File "C:\Users\noudy\PycharmProjects\untitled2\PLS\lib\site-packages\flask_login\utils.py", line 272, in decorated_view
    return func(*args, **kwargs)
  File "C:\Users\noudy\PycharmProjects\PLS\app\new_study\routes.py", line 433, in use_standard_questions_questionnaire
    corevariable = CoreVariable.query.filter_by(name=corresponding_questiongroup.title,
AttributeError: 'NoneType' object has no attribute 'title'
2021-11-19 14:20:55,056 INFO: Microblog startup [in C:\Users\noudy\PycharmProjects\PLS\app\__init__.py:78]
2021-11-19 14:21:19,196 INFO: Microblog startup [in C:\Users\noudy\PycharmProjects\PLS\app\__init__.py:78]
2021-11-19 14:21:45,024 INFO: Microblog startup [in C:\Users\noudy\PycharmProjects\PLS\app\__init__.py:78]
2021-11-19 14:21:47,505 ERROR: Exception on /new_study/data_analysis/4fd4455c-f3c0-4415-a057-f3471ffdb6a3 [GET] [in C:\Users\noudy\PycharmProjects\untitled2\PLS\lib\site-packages\flask\app.py:1457]
Traceback (most recent call last):
  File "C:\Users\noudy\PycharmProjects\untitled2\PLS\lib\site-packages\pandas\core\indexes\base.py", line 3361, in get_loc
    return self._engine.get_loc(casted_key)
  File "pandas\_libs\index.pyx", line 76, in pandas._libs.index.IndexEngine.get_loc
  File "pandas\_libs\index.pyx", line 108, in pandas._libs.index.IndexEngine.get_loc
  File "pandas\_libs\hashtable_class_helper.pxi", line 5198, in pandas._libs.hashtable.PyObjectHashTable.get_item
  File "pandas\_libs\hashtable_class_helper.pxi", line 5206, in pandas._libs.hashtable.PyObjectHashTable.get_item
KeyError: 0

The above exception was the direct cause of the following exception:

Traceback (most recent call last):
  File "C:\Users\noudy\PycharmProjects\untitled2\PLS\lib\site-packages\flask\app.py", line 2073, in wsgi_app
    response = self.full_dispatch_request()
  File "C:\Users\noudy\PycharmProjects\untitled2\PLS\lib\site-packages\flask\app.py", line 1518, in full_dispatch_request
    rv = self.handle_user_exception(e)
  File "C:\Users\noudy\PycharmProjects\untitled2\PLS\lib\site-packages\flask\app.py", line 1516, in full_dispatch_request
    rv = self.dispatch_request()
  File "C:\Users\noudy\PycharmProjects\untitled2\PLS\lib\site-packages\flask\app.py", line 1502, in dispatch_request
    return self.ensure_sync(self.view_functions[rule.endpoint])(**req.view_args)
  File "C:\Users\noudy\PycharmProjects\untitled2\PLS\lib\site-packages\flask_login\utils.py", line 272, in decorated_view
    return func(*args, **kwargs)
  File "C:\Users\noudy\PycharmProjects\PLS\app\new_study\routes.py", line 843, in data_analysis
    print(type(plspm_calc.inner_summary()[0]))
  File "C:\Users\noudy\PycharmProjects\untitled2\PLS\lib\site-packages\pandas\core\frame.py", line 3458, in __getitem__
    indexer = self.columns.get_loc(key)
  File "C:\Users\noudy\PycharmProjects\untitled2\PLS\lib\site-packages\pandas\core\indexes\base.py", line 3363, in get_loc
    raise KeyError(key) from err
KeyError: 0
2021-11-19 14:22:40,186 INFO: Microblog startup [in C:\Users\noudy\PycharmProjects\PLS\app\__init__.py:78]
2021-11-19 14:24:58,648 INFO: Microblog startup [in C:\Users\noudy\PycharmProjects\PLS\app\__init__.py:78]
2021-11-22 10:12:44,371 INFO: Microblog startup [in C:\Users\noudy\PycharmProjects\PLS\app\__init__.py:78]
