2021-11-10 12:03:48,222 ERROR: Exception on /new_study/add_user/Jesus Christ [POST] [in C:\Users\noudy\PycharmProjects\PLS\venv\lib\site-packages\flask\app.py:1457]
Traceback (most recent call last):
  File "C:\Users\noudy\PycharmProjects\PLS\venv\lib\site-packages\flask\app.py", line 2073, in wsgi_app
    response = self.full_dispatch_request()
  File "C:\Users\noudy\PycharmProjects\PLS\venv\lib\site-packages\flask\app.py", line 1518, in full_dispatch_request
    rv = self.handle_user_exception(e)
  File "C:\Users\noudy\PycharmProjects\PLS\venv\lib\site-packages\flask\app.py", line 1516, in full_dispatch_request
    rv = self.dispatch_request()
  File "C:\Users\noudy\PycharmProjects\PLS\venv\lib\site-packages\flask\app.py", line 1502, in dispatch_request
    return self.ensure_sync(self.view_functions[rule.endpoint])(**req.view_args)
  File "C:\Users\noudy\PycharmProjects\PLS\venv\lib\site-packages\flask_login\utils.py", line 272, in decorated_view
    return func(*args, **kwargs)
  File "C:\Users\noudy\PycharmProjects\PLS\app\new_study\routes.py", line 101, in add_user
    form.validate_username()
  File "C:\Users\noudy\PycharmProjects\PLS\app\new_study\forms.py", line 32, in validate_username
    raise ValidationError('This user does not exist.')
wtforms.validators.ValidationError: This user does not exist.
2021-11-10 12:04:08,368 ERROR: Exception on /new_study/add_user/Jesus Christ [POST] [in C:\Users\noudy\PycharmProjects\PLS\venv\lib\site-packages\flask\app.py:1457]
Traceback (most recent call last):
  File "C:\Users\noudy\PycharmProjects\PLS\venv\lib\site-packages\flask\app.py", line 2073, in wsgi_app
    response = self.full_dispatch_request()
  File "C:\Users\noudy\PycharmProjects\PLS\venv\lib\site-packages\flask\app.py", line 1518, in full_dispatch_request
    rv = self.handle_user_exception(e)
  File "C:\Users\noudy\PycharmProjects\PLS\venv\lib\site-packages\flask\app.py", line 1516, in full_dispatch_request
    rv = self.dispatch_request()
  File "C:\Users\noudy\PycharmProjects\PLS\venv\lib\site-packages\flask\app.py", line 1502, in dispatch_request
    return self.ensure_sync(self.view_functions[rule.endpoint])(**req.view_args)
  File "C:\Users\noudy\PycharmProjects\PLS\venv\lib\site-packages\flask_login\utils.py", line 272, in decorated_view
    return func(*args, **kwargs)
  File "C:\Users\noudy\PycharmProjects\PLS\app\new_study\routes.py", line 101, in add_user
    form.validate_username()
  File "C:\Users\noudy\PycharmProjects\PLS\app\new_study\forms.py", line 32, in validate_username
    raise ValidationError('This user does not exist.')
wtforms.validators.ValidationError: This user does not exist.
2021-11-10 12:46:38,966 INFO: Microblog startup [in C:\Users\noudy\PycharmProjects\PLS\app\__init__.py:77]
2021-11-10 12:47:34,683 INFO: Microblog startup [in C:\Users\noudy\PycharmProjects\PLS\app\__init__.py:77]
2021-11-10 13:06:16,694 INFO: Microblog startup [in C:\Users\noudy\PycharmProjects\PLS\app\__init__.py:77]
2021-11-10 13:06:19,214 INFO: Microblog startup [in C:\Users\noudy\PycharmProjects\PLS\app\__init__.py:77]
2021-11-10 13:09:20,942 INFO: Microblog startup [in C:\Users\noudy\PycharmProjects\PLS\app\__init__.py:77]
2021-11-10 13:21:52,669 INFO: Microblog startup [in C:\Users\noudy\PycharmProjects\PLS\app\__init__.py:77]
2021-11-10 13:42:06,266 INFO: Microblog startup [in C:\Users\noudy\PycharmProjects\PLS\app\__init__.py:77]
2021-11-10 13:43:13,621 INFO: Microblog startup [in C:\Users\noudy\PycharmProjects\PLS\app\__init__.py:77]
2021-11-10 13:43:25,767 ERROR: Exception on /new_study/pre_questionnaire/Jesus Christ [POST] [in C:\Users\noudy\PycharmProjects\PLS\venv\lib\site-packages\flask\app.py:1457]
Traceback (most recent call last):
  File "C:\Users\noudy\PycharmProjects\PLS\venv\lib\site-packages\flask\app.py", line 2073, in wsgi_app
    response = self.full_dispatch_request()
  File "C:\Users\noudy\PycharmProjects\PLS\venv\lib\site-packages\flask\app.py", line 1518, in full_dispatch_request
    rv = self.handle_user_exception(e)
  File "C:\Users\noudy\PycharmProjects\PLS\venv\lib\site-packages\flask\app.py", line 1516, in full_dispatch_request
    rv = self.dispatch_request()
  File "C:\Users\noudy\PycharmProjects\PLS\venv\lib\site-packages\flask\app.py", line 1502, in dispatch_request
    return self.ensure_sync(self.view_functions[rule.endpoint])(**req.view_args)
  File "C:\Users\noudy\PycharmProjects\PLS\venv\lib\site-packages\flask_login\utils.py", line 272, in decorated_view
    return func(*args, **kwargs)
  File "C:\Users\noudy\PycharmProjects\PLS\app\new_study\routes.py", line 340, in pre_questionnaire
    if form.validate_on_submit():
  File "C:\Users\noudy\PycharmProjects\PLS\venv\lib\site-packages\flask_wtf\form.py", line 100, in validate_on_submit
    return self.is_submitted() and self.validate()
  File "C:\Users\noudy\PycharmProjects\PLS\venv\lib\site-packages\wtforms\form.py", line 318, in validate
    return super(Form, self).validate(extra)
  File "C:\Users\noudy\PycharmProjects\PLS\venv\lib\site-packages\wtforms\form.py", line 150, in validate
    if not field.validate(self, extra):
  File "C:\Users\noudy\PycharmProjects\PLS\venv\lib\site-packages\wtforms\fields\core.py", line 226, in validate
    stop_validation = self._run_validation_chain(form, chain)
  File "C:\Users\noudy\PycharmProjects\PLS\venv\lib\site-packages\wtforms\fields\core.py", line 246, in _run_validation_chain
    validator(form, self)
  File "C:\Users\noudy\PycharmProjects\PLS\venv\lib\site-packages\wtforms\validators.py", line 104, in __call__
    l = field.data and len(field.data) or 0
TypeError: object of type 'int' has no len()
2021-11-10 13:44:58,396 INFO: Microblog startup [in C:\Users\noudy\PycharmProjects\PLS\app\__init__.py:77]
2021-11-10 13:49:20,394 INFO: Microblog startup [in C:\Users\noudy\PycharmProjects\PLS\app\__init__.py:77]
2021-11-10 14:24:57,254 INFO: Microblog startup [in C:\Users\noudy\PycharmProjects\PLS\app\__init__.py:77]
2021-11-10 14:25:12,720 INFO: Microblog startup [in C:\Users\noudy\PycharmProjects\PLS\app\__init__.py:77]
2021-11-10 14:25:27,035 INFO: Microblog startup [in C:\Users\noudy\PycharmProjects\PLS\app\__init__.py:77]
2021-11-10 14:26:25,207 INFO: Microblog startup [in C:\Users\noudy\PycharmProjects\PLS\app\__init__.py:77]
2021-11-10 14:27:25,119 INFO: Microblog startup [in C:\Users\noudy\PycharmProjects\PLS\app\__init__.py:77]
2021-11-10 14:30:01,328 INFO: Microblog startup [in C:\Users\noudy\PycharmProjects\PLS\app\__init__.py:77]
2021-11-10 14:30:05,467 INFO: Microblog startup [in C:\Users\noudy\PycharmProjects\PLS\app\__init__.py:77]
2021-11-10 14:30:26,988 INFO: Microblog startup [in C:\Users\noudy\PycharmProjects\PLS\app\__init__.py:77]
2021-11-10 14:31:21,843 INFO: Microblog startup [in C:\Users\noudy\PycharmProjects\PLS\app\__init__.py:77]
2021-11-10 14:34:02,716 INFO: Microblog startup [in C:\Users\noudy\PycharmProjects\PLS\app\__init__.py:77]
2021-11-10 14:48:55,916 INFO: Microblog startup [in C:\Users\noudy\PycharmProjects\PLS\app\__init__.py:77]
2021-11-10 15:00:45,375 INFO: Microblog startup [in C:\Users\noudy\PycharmProjects\PLS\app\__init__.py:77]
2021-11-10 15:03:09,800 INFO: Microblog startup [in C:\Users\noudy\PycharmProjects\PLS\app\__init__.py:77]
2021-11-10 15:03:59,298 ERROR: Exception on /d/e/832229c1-018e-4c2d-945b-1a511e48ce90 [GET] [in C:\Users\noudy\PycharmProjects\PLS\venv\lib\site-packages\flask\app.py:1457]
Traceback (most recent call last):
  File "C:\Users\noudy\PycharmProjects\PLS\venv\lib\site-packages\flask\app.py", line 2073, in wsgi_app
    response = self.full_dispatch_request()
  File "C:\Users\noudy\PycharmProjects\PLS\venv\lib\site-packages\flask\app.py", line 1518, in full_dispatch_request
    rv = self.handle_user_exception(e)
  File "C:\Users\noudy\PycharmProjects\PLS\venv\lib\site-packages\flask\app.py", line 1516, in full_dispatch_request
    rv = self.dispatch_request()
  File "C:\Users\noudy\PycharmProjects\PLS\venv\lib\site-packages\flask\app.py", line 1502, in dispatch_request
    return self.ensure_sync(self.view_functions[rule.endpoint])(**req.view_args)
  File "C:\Users\noudy\PycharmProjects\PLS\app\main\routes.py", line 189, in intro_questionlist
    questionnaire = Questionnaire.query.filter_by(study_id=study.id).first()
AttributeError: 'NoneType' object has no attribute 'id'
2021-11-10 19:19:05,550 INFO: Microblog startup [in C:\Users\noudy\PycharmProjects\PLS\app\__init__.py:77]
2021-11-10 20:38:55,540 INFO: Microblog startup [in C:\Users\noudy\PycharmProjects\PLS\app\__init__.py:77]
2021-11-10 20:43:42,753 INFO: Microblog startup [in C:\Users\noudy\PycharmProjects\PLS\app\__init__.py:77]
2021-11-10 20:44:15,074 INFO: Microblog startup [in C:\Users\noudy\PycharmProjects\PLS\app\__init__.py:77]
2021-11-10 20:45:46,251 INFO: Microblog startup [in C:\Users\noudy\PycharmProjects\PLS\app\__init__.py:77]
2021-11-10 20:50:10,205 INFO: Microblog startup [in C:\Users\noudy\PycharmProjects\PLS\app\__init__.py:77]
2021-11-11 10:14:01,584 INFO: Microblog startup [in C:\Users\noudy\PycharmProjects\PLS\app\__init__.py:77]
2021-11-11 10:27:43,569 INFO: Microblog startup [in C:\Users\noudy\PycharmProjects\PLS\app\__init__.py:77]
