2021-12-01 11:44:13,770 ERROR: Exception on /new_study/data_analysis/4fd4455c-f3c0-4415-a057-f3471ffdb6a3 [GET] [in C:\Users\noudy\PycharmProjects\untitled2\PLS\lib\site-packages\flask\app.py:1457]
Traceback (most recent call last):
  File "C:\Users\noudy\PycharmProjects\untitled2\PLS\lib\site-packages\flask\app.py", line 2073, in wsgi_app
    response = self.full_dispatch_request()
  File "C:\Users\noudy\PycharmProjects\untitled2\PLS\lib\site-packages\flask\app.py", line 1518, in full_dispatch_request
    rv = self.handle_user_exception(e)
  File "C:\Users\noudy\PycharmProjects\untitled2\PLS\lib\site-packages\flask\app.py", line 1516, in full_dispatch_request
    rv = self.dispatch_request()
  File "C:\Users\noudy\PycharmProjects\untitled2\PLS\lib\site-packages\flask\app.py", line 1502, in dispatch_request
    return self.ensure_sync(self.view_functions[rule.endpoint])(**req.view_args)
  File "C:\Users\noudy\PycharmProjects\untitled2\PLS\lib\site-packages\flask_login\utils.py", line 272, in decorated_view
    return func(*args, **kwargs)
  File "C:\Users\noudy\PycharmProjects\PLS\app\new_study\routes.py", line 854, in data_analysis
    return render_template('new_study/data_analysis.html', study_code=study_code, data_construct_validity=data_construct_validity,
  File "C:\Users\noudy\PycharmProjects\untitled2\PLS\lib\site-packages\flask\templating.py", line 147, in render_template
    return _render(
  File "C:\Users\noudy\PycharmProjects\untitled2\PLS\lib\site-packages\flask\templating.py", line 128, in _render
    rv = template.render(context)
  File "C:\Users\noudy\PycharmProjects\untitled2\PLS\lib\site-packages\jinja2\environment.py", line 1291, in render
    self.environment.handle_exception()
  File "C:\Users\noudy\PycharmProjects\untitled2\PLS\lib\site-packages\jinja2\environment.py", line 925, in handle_exception
    raise rewrite_traceback_stack(source=source)
  File "C:\Users\noudy\PycharmProjects\PLS\app\templates\new_study\data_analysis.html", line 3, in top-level template code
    {% block app_content %}
  File "C:\Users\noudy\PycharmProjects\PLS\app\templates\new_study\data_analysis.html", line 48, in block 'app_content'
    {% for i in range(dictionary[variable]) %}
TypeError: 'list' object cannot be interpreted as an integer
2021-12-01 11:45:06,863 INFO: Microblog startup [in C:\Users\noudy\PycharmProjects\PLS\app\__init__.py:78]
2021-12-01 11:45:28,130 ERROR: Exception on /new_study/data_analysis/4fd4455c-f3c0-4415-a057-f3471ffdb6a3 [GET] [in C:\Users\noudy\PycharmProjects\untitled2\PLS\lib\site-packages\flask\app.py:1457]
Traceback (most recent call last):
  File "C:\Users\noudy\PycharmProjects\untitled2\PLS\lib\site-packages\flask\app.py", line 2073, in wsgi_app
    response = self.full_dispatch_request()
  File "C:\Users\noudy\PycharmProjects\untitled2\PLS\lib\site-packages\flask\app.py", line 1518, in full_dispatch_request
    rv = self.handle_user_exception(e)
  File "C:\Users\noudy\PycharmProjects\untitled2\PLS\lib\site-packages\flask\app.py", line 1516, in full_dispatch_request
    rv = self.dispatch_request()
  File "C:\Users\noudy\PycharmProjects\untitled2\PLS\lib\site-packages\flask\app.py", line 1502, in dispatch_request
    return self.ensure_sync(self.view_functions[rule.endpoint])(**req.view_args)
  File "C:\Users\noudy\PycharmProjects\untitled2\PLS\lib\site-packages\flask_login\utils.py", line 272, in decorated_view
    return func(*args, **kwargs)
  File "C:\Users\noudy\PycharmProjects\PLS\app\new_study\routes.py", line 854, in data_analysis
    return render_template('new_study/data_analysis.html', study_code=study_code, data_construct_validity=data_construct_validity,
  File "C:\Users\noudy\PycharmProjects\untitled2\PLS\lib\site-packages\flask\templating.py", line 147, in render_template
    return _render(
  File "C:\Users\noudy\PycharmProjects\untitled2\PLS\lib\site-packages\flask\templating.py", line 128, in _render
    rv = template.render(context)
  File "C:\Users\noudy\PycharmProjects\untitled2\PLS\lib\site-packages\jinja2\environment.py", line 1291, in render
    self.environment.handle_exception()
  File "C:\Users\noudy\PycharmProjects\untitled2\PLS\lib\site-packages\jinja2\environment.py", line 925, in handle_exception
    raise rewrite_traceback_stack(source=source)
  File "C:\Users\noudy\PycharmProjects\PLS\app\templates\new_study\data_analysis.html", line 3, in top-level template code
    {% block app_content %}
  File "C:\Users\noudy\PycharmProjects\PLS\app\templates\new_study\data_analysis.html", line 48, in block 'app_content'
    {% for i in range(len(dictionary[variable])) %}
  File "C:\Users\noudy\PycharmProjects\untitled2\PLS\lib\site-packages\jinja2\utils.py", line 84, in from_obj
    if hasattr(obj, "jinja_pass_arg"):
jinja2.exceptions.UndefinedError: 'len' is undefined
2021-12-01 11:46:22,437 INFO: Microblog startup [in C:\Users\noudy\PycharmProjects\PLS\app\__init__.py:78]
2021-12-01 11:46:46,301 ERROR: Exception on /new_study/data_analysis/4fd4455c-f3c0-4415-a057-f3471ffdb6a3 [GET] [in C:\Users\noudy\PycharmProjects\untitled2\PLS\lib\site-packages\flask\app.py:1457]
Traceback (most recent call last):
  File "C:\Users\noudy\PycharmProjects\untitled2\PLS\lib\site-packages\flask\app.py", line 2073, in wsgi_app
    response = self.full_dispatch_request()
  File "C:\Users\noudy\PycharmProjects\untitled2\PLS\lib\site-packages\flask\app.py", line 1518, in full_dispatch_request
    rv = self.handle_user_exception(e)
  File "C:\Users\noudy\PycharmProjects\untitled2\PLS\lib\site-packages\flask\app.py", line 1516, in full_dispatch_request
    rv = self.dispatch_request()
  File "C:\Users\noudy\PycharmProjects\untitled2\PLS\lib\site-packages\flask\app.py", line 1502, in dispatch_request
    return self.ensure_sync(self.view_functions[rule.endpoint])(**req.view_args)
  File "C:\Users\noudy\PycharmProjects\untitled2\PLS\lib\site-packages\flask_login\utils.py", line 272, in decorated_view
    return func(*args, **kwargs)
  File "C:\Users\noudy\PycharmProjects\PLS\app\new_study\routes.py", line 854, in data_analysis
    return render_template('new_study/data_analysis.html', study_code=study_code, data_construct_validity=data_construct_validity,
  File "C:\Users\noudy\PycharmProjects\untitled2\PLS\lib\site-packages\flask\templating.py", line 147, in render_template
    return _render(
  File "C:\Users\noudy\PycharmProjects\untitled2\PLS\lib\site-packages\flask\templating.py", line 128, in _render
    rv = template.render(context)
  File "C:\Users\noudy\PycharmProjects\untitled2\PLS\lib\site-packages\jinja2\environment.py", line 1291, in render
    self.environment.handle_exception()
  File "C:\Users\noudy\PycharmProjects\untitled2\PLS\lib\site-packages\jinja2\environment.py", line 925, in handle_exception
    raise rewrite_traceback_stack(source=source)
  File "C:\Users\noudy\PycharmProjects\PLS\app\templates\new_study\data_analysis.html", line 3, in top-level template code
    {% block app_content %}
  File "C:\Users\noudy\PycharmProjects\PLS\app\templates\new_study\data_analysis.html", line 48, in block 'app_content'
    {% for i in range(length(dictionary[variable])) %}
  File "C:\Users\noudy\PycharmProjects\untitled2\PLS\lib\site-packages\jinja2\utils.py", line 84, in from_obj
    if hasattr(obj, "jinja_pass_arg"):
jinja2.exceptions.UndefinedError: 'length' is undefined
2021-12-01 13:11:23,363 INFO: Microblog startup [in C:\Users\noudy\PycharmProjects\PLS\app\__init__.py:78]
2021-12-01 13:12:42,933 INFO: Microblog startup [in C:\Users\noudy\PycharmProjects\PLS\app\__init__.py:78]
2021-12-01 13:20:17,633 INFO: Microblog startup [in C:\Users\noudy\PycharmProjects\PLS\app\__init__.py:78]
2021-12-01 13:22:21,542 INFO: Microblog startup [in C:\Users\noudy\PycharmProjects\PLS\app\__init__.py:78]
2021-12-01 13:24:51,862 INFO: Microblog startup [in C:\Users\noudy\PycharmProjects\PLS\app\__init__.py:78]
2021-12-01 15:13:04,656 INFO: Microblog startup [in C:\Users\noudy\PycharmProjects\PLS\app\__init__.py:78]
