2021-11-22 10:13:01,091 ERROR: Exception on /new_study/data_analysis/4fd4455c-f3c0-4415-a057-f3471ffdb6a3 [GET] [in C:\Users\noudy\PycharmProjects\untitled2\PLS\lib\site-packages\flask\app.py:1457]
Traceback (most recent call last):
  File "C:\Users\noudy\PycharmProjects\untitled2\PLS\lib\site-packages\flask\app.py", line 2073, in wsgi_app
    response = self.full_dispatch_request()
  File "C:\Users\noudy\PycharmProjects\untitled2\PLS\lib\site-packages\flask\app.py", line 1518, in full_dispatch_request
    rv = self.handle_user_exception(e)
  File "C:\Users\noudy\PycharmProjects\untitled2\PLS\lib\site-packages\flask\app.py", line 1516, in full_dispatch_request
    rv = self.dispatch_request()
  File "C:\Users\noudy\PycharmProjects\untitled2\PLS\lib\site-packages\flask\app.py", line 1502, in dispatch_request
    return self.ensure_sync(self.view_functions[rule.endpoint])(**req.view_args)
  File "C:\Users\noudy\PycharmProjects\untitled2\PLS\lib\site-packages\flask_login\utils.py", line 272, in decorated_view
    return func(*args, **kwargs)
  File "C:\Users\noudy\PycharmProjects\PLS\app\new_study\routes.py", line 844, in data_analysis
    print(i['t'])
TypeError: string indices must be integers
2021-11-22 10:13:16,470 INFO: Microblog startup [in C:\Users\noudy\PycharmProjects\PLS\app\__init__.py:78]
2021-11-22 10:13:42,757 INFO: Microblog startup [in C:\Users\noudy\PycharmProjects\PLS\app\__init__.py:78]
2021-11-22 10:14:29,686 INFO: Microblog startup [in C:\Users\noudy\PycharmProjects\PLS\app\__init__.py:78]
2021-11-22 10:14:50,045 INFO: Microblog startup [in C:\Users\noudy\PycharmProjects\PLS\app\__init__.py:78]
2021-11-22 10:15:47,873 INFO: Microblog startup [in C:\Users\noudy\PycharmProjects\PLS\app\__init__.py:78]
2021-11-22 10:18:33,944 INFO: Microblog startup [in C:\Users\noudy\PycharmProjects\PLS\app\__init__.py:78]
2021-11-22 10:21:10,759 INFO: Microblog startup [in C:\Users\noudy\PycharmProjects\PLS\app\__init__.py:78]
2021-11-22 10:21:41,863 INFO: Microblog startup [in C:\Users\noudy\PycharmProjects\PLS\app\__init__.py:78]
2021-11-22 10:21:43,069 ERROR: Exception on /new_study/data_analysis/4fd4455c-f3c0-4415-a057-f3471ffdb6a3 [GET] [in C:\Users\noudy\PycharmProjects\untitled2\PLS\lib\site-packages\flask\app.py:1457]
Traceback (most recent call last):
  File "C:\Users\noudy\PycharmProjects\untitled2\PLS\lib\site-packages\pandas\core\indexes\base.py", line 3361, in get_loc
    return self._engine.get_loc(casted_key)
  File "pandas\_libs\index.pyx", line 76, in pandas._libs.index.IndexEngine.get_loc
  File "pandas\_libs\index.pyx", line 108, in pandas._libs.index.IndexEngine.get_loc
  File "pandas\_libs\hashtable_class_helper.pxi", line 5198, in pandas._libs.hashtable.PyObjectHashTable.get_item
  File "pandas\_libs\hashtable_class_helper.pxi", line 5206, in pandas._libs.hashtable.PyObjectHashTable.get_item
KeyError: 1

The above exception was the direct cause of the following exception:

Traceback (most recent call last):
  File "C:\Users\noudy\PycharmProjects\untitled2\PLS\lib\site-packages\flask\app.py", line 2073, in wsgi_app
    response = self.full_dispatch_request()
  File "C:\Users\noudy\PycharmProjects\untitled2\PLS\lib\site-packages\flask\app.py", line 1518, in full_dispatch_request
    rv = self.handle_user_exception(e)
  File "C:\Users\noudy\PycharmProjects\untitled2\PLS\lib\site-packages\flask\app.py", line 1516, in full_dispatch_request
    rv = self.dispatch_request()
  File "C:\Users\noudy\PycharmProjects\untitled2\PLS\lib\site-packages\flask\app.py", line 1502, in dispatch_request
    return self.ensure_sync(self.view_functions[rule.endpoint])(**req.view_args)
  File "C:\Users\noudy\PycharmProjects\untitled2\PLS\lib\site-packages\flask_login\utils.py", line 272, in decorated_view
    return func(*args, **kwargs)
  File "C:\Users\noudy\PycharmProjects\PLS\app\new_study\routes.py", line 845, in data_analysis
    print(coefficients.loc[1])
  File "C:\Users\noudy\PycharmProjects\untitled2\PLS\lib\site-packages\pandas\core\indexing.py", line 931, in __getitem__
    return self._getitem_axis(maybe_callable, axis=axis)
  File "C:\Users\noudy\PycharmProjects\untitled2\PLS\lib\site-packages\pandas\core\indexing.py", line 1164, in _getitem_axis
    return self._get_label(key, axis=axis)
  File "C:\Users\noudy\PycharmProjects\untitled2\PLS\lib\site-packages\pandas\core\indexing.py", line 1113, in _get_label
    return self.obj.xs(label, axis=axis)
  File "C:\Users\noudy\PycharmProjects\untitled2\PLS\lib\site-packages\pandas\core\generic.py", line 3776, in xs
    loc = index.get_loc(key)
  File "C:\Users\noudy\PycharmProjects\untitled2\PLS\lib\site-packages\pandas\core\indexes\base.py", line 3363, in get_loc
    raise KeyError(key) from err
KeyError: 1
2021-11-22 10:22:14,779 INFO: Microblog startup [in C:\Users\noudy\PycharmProjects\PLS\app\__init__.py:78]
2021-11-22 10:24:02,342 INFO: Microblog startup [in C:\Users\noudy\PycharmProjects\PLS\app\__init__.py:78]
2021-11-22 10:24:44,467 INFO: Microblog startup [in C:\Users\noudy\PycharmProjects\PLS\app\__init__.py:78]
2021-11-22 10:30:13,202 INFO: Microblog startup [in C:\Users\noudy\PycharmProjects\PLS\app\__init__.py:78]
2021-11-22 10:32:05,055 INFO: Microblog startup [in C:\Users\noudy\PycharmProjects\PLS\app\__init__.py:78]
2021-11-22 10:34:03,409 INFO: Microblog startup [in C:\Users\noudy\PycharmProjects\PLS\app\__init__.py:78]
2021-11-22 10:35:14,664 INFO: Microblog startup [in C:\Users\noudy\PycharmProjects\PLS\app\__init__.py:78]
2021-11-22 10:36:48,864 INFO: Microblog startup [in C:\Users\noudy\PycharmProjects\PLS\app\__init__.py:78]
2021-11-22 11:04:11,693 INFO: Microblog startup [in C:\Users\noudy\PycharmProjects\PLS\app\__init__.py:78]
2021-11-22 11:19:03,070 INFO: Microblog startup [in C:\Users\noudy\PycharmProjects\PLS\app\__init__.py:78]
2021-11-22 11:31:11,633 INFO: Microblog startup [in C:\Users\noudy\PycharmProjects\PLS\app\__init__.py:78]
2021-11-22 11:32:04,391 INFO: Microblog startup [in C:\Users\noudy\PycharmProjects\PLS\app\__init__.py:78]
2021-11-22 11:32:06,401 ERROR: Exception on /new_study/data_analysis/4fd4455c-f3c0-4415-a057-f3471ffdb6a3 [GET] [in C:\Users\noudy\PycharmProjects\untitled2\PLS\lib\site-packages\flask\app.py:1457]
Traceback (most recent call last):
  File "C:\Users\noudy\PycharmProjects\untitled2\PLS\lib\site-packages\pandas\core\indexes\base.py", line 3361, in get_loc
    return self._engine.get_loc(casted_key)
  File "pandas\_libs\index.pyx", line 76, in pandas._libs.index.IndexEngine.get_loc
  File "pandas\_libs\index.pyx", line 108, in pandas._libs.index.IndexEngine.get_loc
  File "pandas\_libs\hashtable_class_helper.pxi", line 5198, in pandas._libs.hashtable.PyObjectHashTable.get_item
  File "pandas\_libs\hashtable_class_helper.pxi", line 5206, in pandas._libs.hashtable.PyObjectHashTable.get_item
KeyError: 'BI1'

The above exception was the direct cause of the following exception:

Traceback (most recent call last):
  File "C:\Users\noudy\PycharmProjects\untitled2\PLS\lib\site-packages\flask\app.py", line 2073, in wsgi_app
    response = self.full_dispatch_request()
  File "C:\Users\noudy\PycharmProjects\untitled2\PLS\lib\site-packages\flask\app.py", line 1518, in full_dispatch_request
    rv = self.handle_user_exception(e)
  File "C:\Users\noudy\PycharmProjects\untitled2\PLS\lib\site-packages\flask\app.py", line 1516, in full_dispatch_request
    rv = self.dispatch_request()
  File "C:\Users\noudy\PycharmProjects\untitled2\PLS\lib\site-packages\flask\app.py", line 1502, in dispatch_request
    return self.ensure_sync(self.view_functions[rule.endpoint])(**req.view_args)
  File "C:\Users\noudy\PycharmProjects\untitled2\PLS\lib\site-packages\flask_login\utils.py", line 272, in decorated_view
    return func(*args, **kwargs)
  File "C:\Users\noudy\PycharmProjects\PLS\app\new_study\routes.py", line 847, in data_analysis
    print(model1['BI1'])
  File "C:\Users\noudy\PycharmProjects\untitled2\PLS\lib\site-packages\pandas\core\frame.py", line 3458, in __getitem__
    indexer = self.columns.get_loc(key)
  File "C:\Users\noudy\PycharmProjects\untitled2\PLS\lib\site-packages\pandas\core\indexes\base.py", line 3363, in get_loc
    raise KeyError(key) from err
KeyError: 'BI1'
2021-11-22 11:32:26,613 INFO: Microblog startup [in C:\Users\noudy\PycharmProjects\PLS\app\__init__.py:78]
2021-11-22 11:32:44,376 INFO: Microblog startup [in C:\Users\noudy\PycharmProjects\PLS\app\__init__.py:78]
2021-11-22 12:11:00,832 INFO: Microblog startup [in C:\Users\noudy\PycharmProjects\PLS\app\__init__.py:78]
2021-11-22 12:11:17,603 INFO: Microblog startup [in C:\Users\noudy\PycharmProjects\PLS\app\__init__.py:78]
2021-11-22 13:28:59,855 INFO: Microblog startup [in C:\Users\noudy\PycharmProjects\PLS\app\__init__.py:78]
2021-11-22 13:31:04,689 INFO: Microblog startup [in C:\Users\noudy\PycharmProjects\PLS\app\__init__.py:78]
2021-11-22 13:31:34,186 INFO: Microblog startup [in C:\Users\noudy\PycharmProjects\PLS\app\__init__.py:78]
2021-11-22 13:36:16,390 INFO: Microblog startup [in C:\Users\noudy\PycharmProjects\PLS\app\__init__.py:78]
2021-11-22 13:36:31,425 INFO: Microblog startup [in C:\Users\noudy\PycharmProjects\PLS\app\__init__.py:78]
2021-11-22 13:43:48,439 INFO: Microblog startup [in C:\Users\noudy\PycharmProjects\PLS\app\__init__.py:78]
2021-11-22 13:45:23,827 INFO: Microblog startup [in C:\Users\noudy\PycharmProjects\PLS\app\__init__.py:78]
2021-11-22 13:45:41,171 INFO: Microblog startup [in C:\Users\noudy\PycharmProjects\PLS\app\__init__.py:78]
2021-11-22 13:46:19,253 INFO: Microblog startup [in C:\Users\noudy\PycharmProjects\PLS\app\__init__.py:78]
2021-11-22 13:46:43,202 INFO: Microblog startup [in C:\Users\noudy\PycharmProjects\PLS\app\__init__.py:78]
2021-11-22 13:47:09,885 INFO: Microblog startup [in C:\Users\noudy\PycharmProjects\PLS\app\__init__.py:78]
2021-11-22 13:47:32,756 INFO: Microblog startup [in C:\Users\noudy\PycharmProjects\PLS\app\__init__.py:78]
2021-11-22 13:53:59,154 INFO: Microblog startup [in C:\Users\noudy\PycharmProjects\PLS\app\__init__.py:78]
