2021-11-18 11:34:01,871 ERROR: Exception on /new_study/data_analysis/7431d4a5-bbe8-47c2-828f-877210b9cceb [GET] [in C:\Users\noudy\PycharmProjects\untitled2\PLS\lib\site-packages\flask\app.py:1457]
Traceback (most recent call last):
  File "C:\Users\noudy\PycharmProjects\untitled2\PLS\lib\site-packages\flask\app.py", line 2073, in wsgi_app
    response = self.full_dispatch_request()
  File "C:\Users\noudy\PycharmProjects\untitled2\PLS\lib\site-packages\flask\app.py", line 1518, in full_dispatch_request
    rv = self.handle_user_exception(e)
  File "C:\Users\noudy\PycharmProjects\untitled2\PLS\lib\site-packages\flask\app.py", line 1516, in full_dispatch_request
    rv = self.dispatch_request()
  File "C:\Users\noudy\PycharmProjects\untitled2\PLS\lib\site-packages\flask\app.py", line 1502, in dispatch_request
    return self.ensure_sync(self.view_functions[rule.endpoint])(**req.view_args)
  File "C:\Users\noudy\PycharmProjects\untitled2\PLS\lib\site-packages\flask_login\utils.py", line 272, in decorated_view
    return func(*args, **kwargs)
  File "C:\Users\noudy\PycharmProjects\PLS\app\new_study\routes.py", line 823, in data_analysis
    df = pd.read_excel(name_study + '.xlsx')
  File "C:\Users\noudy\PycharmProjects\untitled2\PLS\lib\site-packages\pandas\util\_decorators.py", line 311, in wrapper
    return func(*args, **kwargs)
  File "C:\Users\noudy\PycharmProjects\untitled2\PLS\lib\site-packages\pandas\io\excel\_base.py", line 364, in read_excel
    io = ExcelFile(io, storage_options=storage_options, engine=engine)
  File "C:\Users\noudy\PycharmProjects\untitled2\PLS\lib\site-packages\pandas\io\excel\_base.py", line 1191, in __init__
    ext = inspect_excel_format(
  File "C:\Users\noudy\PycharmProjects\untitled2\PLS\lib\site-packages\pandas\io\excel\_base.py", line 1070, in inspect_excel_format
    with get_handle(
  File "C:\Users\noudy\PycharmProjects\untitled2\PLS\lib\site-packages\pandas\io\common.py", line 711, in get_handle
    handle = open(handle, ioargs.mode)
FileNotFoundError: [Errno 2] No such file or directory: 'The study of the jive of happiness.xlsx'
2021-11-18 11:48:42,716 INFO: Microblog startup [in C:\Users\noudy\PycharmProjects\PLS\app\__init__.py:78]
2021-11-18 11:48:44,682 ERROR: Exception on /new_study/data_analysis/7431d4a5-bbe8-47c2-828f-877210b9cceb [GET] [in C:\Users\noudy\PycharmProjects\untitled2\PLS\lib\site-packages\flask\app.py:1457]
Traceback (most recent call last):
  File "C:\Users\noudy\PycharmProjects\untitled2\PLS\lib\site-packages\flask\app.py", line 2073, in wsgi_app
    response = self.full_dispatch_request()
  File "C:\Users\noudy\PycharmProjects\untitled2\PLS\lib\site-packages\flask\app.py", line 1518, in full_dispatch_request
    rv = self.handle_user_exception(e)
  File "C:\Users\noudy\PycharmProjects\untitled2\PLS\lib\site-packages\flask\app.py", line 1516, in full_dispatch_request
    rv = self.dispatch_request()
  File "C:\Users\noudy\PycharmProjects\untitled2\PLS\lib\site-packages\flask\app.py", line 1502, in dispatch_request
    return self.ensure_sync(self.view_functions[rule.endpoint])(**req.view_args)
  File "C:\Users\noudy\PycharmProjects\untitled2\PLS\lib\site-packages\flask_login\utils.py", line 272, in decorated_view
    return func(*args, **kwargs)
  File "C:\Users\noudy\PycharmProjects\PLS\app\new_study\routes.py", line 829, in data_analysis
    worksheet.write(excel_style(1, column), question.question_code)
NameError: name 'worksheet' is not defined
2021-11-18 11:49:25,845 INFO: Microblog startup [in C:\Users\noudy\PycharmProjects\PLS\app\__init__.py:78]
2021-11-18 16:49:31,036 INFO: Microblog startup [in C:\Users\noudy\PycharmProjects\PLS\app\__init__.py:78]
2021-11-18 16:49:39,943 ERROR: Exception on /new_study/data_analysis/a13a3037-1e65-4b4b-896e-c06a397e24d5 [GET] [in C:\Users\noudy\PycharmProjects\untitled2\PLS\lib\site-packages\flask\app.py:1457]
Traceback (most recent call last):
  File "C:\Users\noudy\PycharmProjects\untitled2\PLS\lib\site-packages\flask\app.py", line 2073, in wsgi_app
    response = self.full_dispatch_request()
  File "C:\Users\noudy\PycharmProjects\untitled2\PLS\lib\site-packages\flask\app.py", line 1518, in full_dispatch_request
    rv = self.handle_user_exception(e)
  File "C:\Users\noudy\PycharmProjects\untitled2\PLS\lib\site-packages\flask\app.py", line 1516, in full_dispatch_request
    rv = self.dispatch_request()
  File "C:\Users\noudy\PycharmProjects\untitled2\PLS\lib\site-packages\flask\app.py", line 1502, in dispatch_request
    return self.ensure_sync(self.view_functions[rule.endpoint])(**req.view_args)
  File "C:\Users\noudy\PycharmProjects\untitled2\PLS\lib\site-packages\flask_login\utils.py", line 272, in decorated_view
    return func(*args, **kwargs)
  File "C:\Users\noudy\PycharmProjects\PLS\app\new_study\routes.py", line 827, in data_analysis
    config.add_lv_with_columns_named(corevariable.abbreviation, Mode.A, df, corevariable.abbreviation)
  File "C:\Users\noudy\PycharmProjects\untitled2\PLS\lib\site-packages\plspm\config.py", line 242, in add_lv_with_columns_named
    mvs = list(map(lambda mv: MV(mv, default_scale), names))
  File "C:\Users\noudy\PycharmProjects\untitled2\PLS\lib\site-packages\plspm\config.py", line 241, in <lambda>
    names = filter(lambda x: x.startswith(col_name_starts_with), list(data))
AttributeError: 'NoneType' object has no attribute 'startswith'
2021-11-18 16:50:07,424 INFO: Microblog startup [in C:\Users\noudy\PycharmProjects\PLS\app\__init__.py:78]
2021-11-18 16:50:07,541 ERROR: Exception on /new_study/data_analysis/a13a3037-1e65-4b4b-896e-c06a397e24d5 [GET] [in C:\Users\noudy\PycharmProjects\untitled2\PLS\lib\site-packages\flask\app.py:1457]
Traceback (most recent call last):
  File "C:\Users\noudy\PycharmProjects\untitled2\PLS\lib\site-packages\flask\app.py", line 2073, in wsgi_app
    response = self.full_dispatch_request()
  File "C:\Users\noudy\PycharmProjects\untitled2\PLS\lib\site-packages\flask\app.py", line 1518, in full_dispatch_request
    rv = self.handle_user_exception(e)
  File "C:\Users\noudy\PycharmProjects\untitled2\PLS\lib\site-packages\flask\app.py", line 1516, in full_dispatch_request
    rv = self.dispatch_request()
  File "C:\Users\noudy\PycharmProjects\untitled2\PLS\lib\site-packages\flask\app.py", line 1502, in dispatch_request
    return self.ensure_sync(self.view_functions[rule.endpoint])(**req.view_args)
  File "C:\Users\noudy\PycharmProjects\untitled2\PLS\lib\site-packages\flask_login\utils.py", line 272, in decorated_view
    return func(*args, **kwargs)
  File "C:\Users\noudy\PycharmProjects\PLS\app\new_study\routes.py", line 828, in data_analysis
    config.add_lv_with_columns_named(corevariable.abbreviation, Mode.A, df, corevariable.abbreviation)
  File "C:\Users\noudy\PycharmProjects\untitled2\PLS\lib\site-packages\plspm\config.py", line 242, in add_lv_with_columns_named
    mvs = list(map(lambda mv: MV(mv, default_scale), names))
  File "C:\Users\noudy\PycharmProjects\untitled2\PLS\lib\site-packages\plspm\config.py", line 241, in <lambda>
    names = filter(lambda x: x.startswith(col_name_starts_with), list(data))
AttributeError: 'NoneType' object has no attribute 'startswith'
2021-11-18 16:50:39,988 INFO: Microblog startup [in C:\Users\noudy\PycharmProjects\PLS\app\__init__.py:78]
2021-11-18 16:50:40,263 ERROR: Exception on /new_study/data_analysis/a13a3037-1e65-4b4b-896e-c06a397e24d5 [GET] [in C:\Users\noudy\PycharmProjects\untitled2\PLS\lib\site-packages\flask\app.py:1457]
Traceback (most recent call last):
  File "C:\Users\noudy\PycharmProjects\untitled2\PLS\lib\site-packages\flask\app.py", line 2073, in wsgi_app
    response = self.full_dispatch_request()
  File "C:\Users\noudy\PycharmProjects\untitled2\PLS\lib\site-packages\flask\app.py", line 1518, in full_dispatch_request
    rv = self.handle_user_exception(e)
  File "C:\Users\noudy\PycharmProjects\untitled2\PLS\lib\site-packages\flask\app.py", line 1516, in full_dispatch_request
    rv = self.dispatch_request()
  File "C:\Users\noudy\PycharmProjects\untitled2\PLS\lib\site-packages\flask\app.py", line 1502, in dispatch_request
    return self.ensure_sync(self.view_functions[rule.endpoint])(**req.view_args)
  File "C:\Users\noudy\PycharmProjects\untitled2\PLS\lib\site-packages\flask_login\utils.py", line 272, in decorated_view
    return func(*args, **kwargs)
  File "C:\Users\noudy\PycharmProjects\PLS\app\new_study\routes.py", line 829, in data_analysis
    config.add_lv_with_columns_named(corevariable.abbreviation, Mode.A, df, corevariable.abbreviation)
  File "C:\Users\noudy\PycharmProjects\untitled2\PLS\lib\site-packages\plspm\config.py", line 242, in add_lv_with_columns_named
    mvs = list(map(lambda mv: MV(mv, default_scale), names))
  File "C:\Users\noudy\PycharmProjects\untitled2\PLS\lib\site-packages\plspm\config.py", line 241, in <lambda>
    names = filter(lambda x: x.startswith(col_name_starts_with), list(data))
AttributeError: 'NoneType' object has no attribute 'startswith'
